<?xml version="1.0" encoding="utf-8"?>
<!-- =================================================================================== -->
<!-- |    This document was autogenerated by xacro from yanshee_display.urdf.xacro     | -->
<!-- |    EDITING THIS FILE BY HAND IS NOT RECOMMENDED                                 | -->
<!-- =================================================================================== -->
<robot name="yanshee">
  <link name="world">
    <visual>
      <geometry>
        <sphere radius="0.001"/>
      </geometry>
    </visual>
  </link>
  <link name="base_link">
    <visual>
      <origin rpy="0 0 0" xyz="0 0 0"/>
      <geometry>
        <mesh filename="package://yanshee/meshes/base_link.STL"/>
      </geometry>
      <material name="">
        <color rgba="1 1 1 1"/>
      </material>
    </visual>
  </link>
  <joint name="world_to_base" type="fixed">
    <parent link="world"/>
    <child link="base_link"/>
    <origin rpy="0.0 0.0 0.0" xyz="0.0 0.0 0.3"/>
  </joint>
  <link name="head_Link">
    <visual>
      <origin rpy="0 0 0" xyz="0 0 0"/>
      <geometry>
        <mesh filename="package://yanshee/meshes/head_Link.STL"/>
      </geometry>
      <material name="">
        <color rgba="1 1 1 1"/>
      </material>
    </visual>
  </link>
  <joint name="head_joint" type="revolute">
    <origin rpy="0 0 0" xyz="0 -0.00014945 0.06"/>
    <parent link="base_link"/>
    <child link="head_Link"/>
    <axis xyz="-0.00044678 -0.0035302 0.99999"/>
    <limit effort="1.0" lower="-0.78" upper="0.78" velocity="10"/>
  </joint>
  <link name="left_arm1_Link">
    <visual>
      <origin rpy="0 0 0" xyz="0 0 0"/>
      <geometry>
        <mesh filename="package://yanshee/meshes/left_arm1_Link.STL"/>
      </geometry>
      <material name="">
        <color rgba="1 1 1 1"/>
      </material>
    </visual>
  </link>
  <joint name="left_arm1_joint" type="revolute">
    <origin rpy="-1.5708 0 0" xyz="0.0030003 0.076597 0.013315"/>
    <parent link="base_link"/>
    <child link="left_arm1_Link"/>
    <axis xyz="-5.8802e-05 0 -1"/>
    <limit effort="1" lower="-1.58" upper="1.58" velocity="10"/>
  </joint>
  <link name="left_arm2_Link">
    <visual>
      <origin rpy="0 0 0" xyz="0 0 0"/>
      <geometry>
        <mesh filename="package://yanshee/meshes/left_arm2_Link.STL"/>
      </geometry>
      <material name="">
        <color rgba="1 1 1 1"/>
      </material>
    </visual>
  </link>
  <joint name="left_arm2_joint" type="revolute">
    <origin rpy="1.5708 0 1.5708" xyz="0 0 0"/>
    <parent link="left_arm1_Link"/>
    <child link="left_arm2_Link"/>
    <axis xyz="0 0 1"/>
    <limit effort="1" lower="-1.58" upper="1.58" velocity="10"/>
  </joint>
  <link name="left_arm3_Link">
    <visual>
      <origin rpy="0 0 0" xyz="0 0 0"/>
      <geometry>
        <mesh filename="package://yanshee/meshes/left_arm3_Link.STL"/>
      </geometry>
      <material name="">
        <color rgba="1 1 1 1"/>
      </material>
    </visual>
  </link>
  <joint name="left_arm3_joint" type="revolute">
    <origin rpy="0 0 0" xyz="0.059245 0 0.00152"/>
    <parent link="left_arm2_Link"/>
    <child link="left_arm3_Link"/>
    <axis xyz="0.026177 0 0.99966"/>
    <limit effort="1" lower="-1.58" upper="1.58" velocity="10"/>
  </joint>
  <link name="right_arm1_Link">
    <visual>
      <origin rpy="0 0 0" xyz="0 0 0"/>
      <geometry>
        <mesh filename="package://yanshee/meshes/right_arm1_Link.STL"/>
      </geometry>
      <material name="">
        <color rgba="1 1 1 1"/>
      </material>
    </visual>
  </link>
  <joint name="right_arm1_joint" type="revolute">
    <origin rpy="1.5708 0 0" xyz="0.0030003 -0.077273 0.013316"/>
    <parent link="base_link"/>
    <child link="right_arm1_Link"/>
    <axis xyz="0 0 1"/>
    <limit effort="1" lower="-1.58" upper="1.58" velocity="10"/>
  </joint>
  <link name="right_arm2_Link">
    <visual>
      <origin rpy="0 0 0" xyz="0 0 0"/>
      <geometry>
        <mesh filename="package://yanshee/meshes/right_arm2_Link.STL"/>
      </geometry>
      <material name="">
        <color rgba="1 1 1 1"/>
      </material>
    </visual>
  </link>
  <joint name="right_arm2_joint" type="revolute">
    <origin rpy="1.5708 0 -1.5708" xyz="-9.961e-05 0 0"/>
    <parent link="right_arm1_Link"/>
    <child link="right_arm2_Link"/>
    <axis xyz="0 0 1"/>
    <limit effort="1" lower="-1.58" upper="1.58" velocity="10"/>
  </joint>
  <link name="right_arm3_Link">
    <visual>
      <origin rpy="0 0 0" xyz="0 0 0"/>
      <geometry>
        <mesh filename="package://yanshee/meshes/right_arm3_Link.STL"/>
      </geometry>
      <material name="">
        <color rgba="1 1 1 1"/>
      </material>
    </visual>
  </link>
  <joint name="right_arm3_joint" type="revolute">
    <origin rpy="0 0 0" xyz="0.059245 0 -0.00152"/>
    <parent link="right_arm2_Link"/>
    <child link="right_arm3_Link"/>
    <axis xyz="0 0 -1"/>
    <limit effort="1" lower="-1.58" upper="1.58" velocity="10"/>
  </joint>
  <link name="left_leg1_Link">
    <visual>
      <origin rpy="0 0 0" xyz="0 0 0"/>
      <geometry>
        <mesh filename="package://yanshee/meshes/left_leg1_Link.STL"/>
      </geometry>
      <material name="">
        <color rgba="1 1 1 1"/>
      </material>
    </visual>
  </link>
  <joint name="left_leg1_joint" type="revolute">
    <origin rpy="-1.5708 1.5708 1.5708" xyz="-0.0091403 0.028469 -0.066034"/>
    <parent link="base_link"/>
    <child link="left_leg1_Link"/>
    <axis xyz="0 0 -1"/>
    <limit effort="1" lower="-1.58" upper="1.58" velocity="10"/>
  </joint>
  <link name="left_leg2_Link">
    <visual>
      <origin rpy="0 0 0" xyz="0 0 0"/>
      <geometry>
        <mesh filename="package://yanshee/meshes/left_leg2_Link.STL"/>
      </geometry>
      <material name="">
        <color rgba="1 1 1 1"/>
      </material>
    </visual>
  </link>
  <joint name="left_leg2_joint" type="revolute">
    <origin rpy="1.5708 0 0" xyz="0.0438 0 0"/>
    <parent link="left_leg1_Link"/>
    <child link="left_leg2_Link"/>
    <axis xyz="0 0 -1"/>
    <limit effort="1" lower="-1.58" upper="1.58" velocity="10"/>
  </joint>
  <link name="left_leg3_Link">
    <visual>
      <origin rpy="0 0 0" xyz="0 0 0"/>
      <geometry>
        <mesh filename="package://yanshee/meshes/left_leg3_Link.STL"/>
      </geometry>
      <material name="">
        <color rgba="1 1 1 1"/>
      </material>
    </visual>
  </link>
  <joint name="left_leg3_joint" type="revolute">
    <origin rpy="0 0 0" xyz="0.049876 0 1.4223e-05"/>
    <parent link="left_leg2_Link"/>
    <child link="left_leg3_Link"/>
    <axis xyz="0 0.0007632 -1"/>
    <limit effort="1" lower="-1.58" upper="1.58" velocity="10"/>
  </joint>
  <link name="left_leg4_Link">
    <visual>
      <origin rpy="0 0 0" xyz="0 0 0"/>
      <geometry>
        <mesh filename="package://yanshee/meshes/left_leg4_Link.STL"/>
      </geometry>
      <material name="">
        <color rgba="1 1 1 1"/>
      </material>
    </visual>
  </link>
  <joint name="left_leg4_joint" type="revolute">
    <origin rpy="1.5708 0 0" xyz="0.059245 1.5251e-05 0"/>
    <parent link="left_leg3_Link"/>
    <child link="left_leg4_Link"/>
    <axis xyz="0 -1 0"/>
    <limit effort="1" lower="-1.58" upper="1.58" velocity="10"/>
  </joint>
  <link name="left_leg5_Link">
    <visual>
      <origin rpy="0 0 0" xyz="0 0 0"/>
      <geometry>
        <mesh filename="package://yanshee/meshes/left_leg5_Link.STL"/>
      </geometry>
      <material name="">
        <color rgba="1 1 1 1"/>
      </material>
    </visual>
  </link>
  <joint name="left_leg5_joint" type="revolute">
    <origin rpy="3.1416 0 0" xyz="0.03699 -0.0088627 0"/>
    <parent link="left_leg4_Link"/>
    <child link="left_leg5_Link"/>
    <axis xyz="0 0 -1"/>
    <limit effort="1" lower="-1.58" upper="1.58" velocity="10"/>
  </joint>
  <link name="right_leg1_Link">
    <visual>
      <origin rpy="0 0 0" xyz="0 0 0"/>
      <geometry>
        <mesh filename="package://yanshee/meshes/right_leg1_Link.STL"/>
      </geometry>
      <material name="">
        <color rgba="1 1 1 1"/>
      </material>
    </visual>
  </link>
  <joint name="right_leg1_joint" type="revolute">
    <origin rpy="-1.5708 1.5708 -1.5708" xyz="-0.0091403 -0.028469 -0.066034"/>
    <parent link="base_link"/>
    <child link="right_leg1_Link"/>
    <axis xyz="0 0 1"/>
    <limit effort="1" lower="-1.58" upper="1.58" velocity="10"/>
  </joint>
  <link name="right_leg2_Link">
    <visual>
      <origin rpy="0 0 0" xyz="0 0 0"/>
      <geometry>
        <mesh filename="package://yanshee/meshes/right_leg2_Link.STL"/>
      </geometry>
      <material name="">
        <color rgba="1 1 1 1"/>
      </material>
    </visual>
  </link>
  <joint name="right_leg2_joint" type="revolute">
    <origin rpy="1.5708 0 0" xyz="0.0438 0 0"/>
    <parent link="right_leg1_Link"/>
    <child link="right_leg2_Link"/>
    <axis xyz="0 0 -1"/>
    <limit effort="1" lower="-1.58" upper="1.58" velocity="10"/>
  </joint>
  <link name="right_leg3_Link">
    <visual>
      <origin rpy="0 0 0" xyz="0 0 0"/>
      <geometry>
        <mesh filename="package://yanshee/meshes/right_leg3_Link.STL"/>
      </geometry>
      <material name="">
        <color rgba="1 1 1 1"/>
      </material>
    </visual>
  </link>
  <joint name="right_leg3_joint" type="revolute">
    <origin rpy="0 0 0" xyz="0.049769 0.0032671 1.4223e-05"/>
    <parent link="right_leg2_Link"/>
    <child link="right_leg3_Link"/>
    <axis xyz="0 0.0007632 -1"/>
    <limit effort="1" lower="-1.58" upper="1.58" velocity="10"/>
  </joint>
  <link name="right_leg4_Link">
    <visual>
      <origin rpy="0 0 0" xyz="0 0 0"/>
      <geometry>
        <mesh filename="package://yanshee/meshes/right_leg4_Link.STL"/>
      </geometry>
      <material name="">
        <color rgba="1 1 1 1"/>
      </material>
    </visual>
  </link>
  <joint name="right_leg4_joint" type="revolute">
    <origin rpy="0 0 0" xyz="0.059245 -1.5243e-05 -1.0003e-05"/>
    <parent link="right_leg3_Link"/>
    <child link="right_leg4_Link"/>
    <axis xyz="0 0 -1"/>
    <limit effort="1" lower="-1.58" upper="1.58" velocity="10"/>
  </joint>
  <link name="right_leg5_Link">
    <visual>
      <origin rpy="0 0 0" xyz="0 0 0"/>
      <geometry>
        <mesh filename="package://yanshee/meshes/right_leg5_Link.STL"/>
      </geometry>
      <material name="">
        <color rgba="1 1 1 1"/>
      </material>
    </visual>
  </link>
  <joint name="right_leg5_joint" type="revolute">
    <origin rpy="-1.5708 0 0" xyz="0.03699 0 -0.0088627"/>
    <parent link="right_leg4_Link"/>
    <child link="right_leg5_Link"/>
    <axis xyz="0 0 1"/>
    <limit effort="1" lower="-1.58" upper="1.58" velocity="10"/>
  </joint>
</robot>

