<robot name="left_leg3" xmlns:xacro="http://wiki.ros.org/xacro">
  <xacro:property name="part_name" value="left_leg3" />
  <xacro:property name="origin_x" value="0.0407946525783551" />
  <xacro:property name="origin_y" value="2.00999895415663E-05" />
  <xacro:property name="origin_z" value="0.000215900493275946" />
  <xacro:property name="mass_value" value="0.0769705912620037" />

  <xacro:property name="inertia_ixx" value="2.01778905647826E-05" />
  <xacro:property name="inertia_ixy" value="3.24770412009536E-09" />
  <xacro:property name="inertia_ixz" value="-5.11455121015069E-08" />
  <xacro:property name="inertia_iyy" value="3.91841731233319E-05" />
  <xacro:property name="inertia_iyz" value="1.50114743011987E-09" />
  <xacro:property name="inertia_izz" value="3.21700138167598E-05" />

  <xacro:property name="mesh_file" value="package://yanshee/meshes/left_leg3_Link.STL" />

  <xacro:property name="joint_offset_x" value="0.049876" />
  <xacro:property name="joint_offset_y" value="0" />
  <xacro:property name="joint_offset_z" value="1.4223E-05" />
  <xacro:property name="joint_offset_rr" value="0" />
  <xacro:property name="joint_offset_rp" value="0" />
  <xacro:property name="joint_offset_ry" value="0" />

  <xacro:property name="parent_link" value="left_leg2_Link" />
  <xacro:property name="child_link" value="left_leg3_Link" />

  <xacro:property name="joint_axis_x" value="0" />
  <xacro:property name="joint_axis_y" value="0.0007632" />
  <xacro:property name="joint_axis_z" value="-1" />

  <xacro:property name="joint_limit_lower" value="-1.58" />
  <xacro:property name="joint_limit_upper" value="1.58" />
  <xacro:property name="joint_limit_effort" value="1" />
  <xacro:property name="joint_limit_velocity" value="10" />





  <link name="${part_name}_Link">
    <inertial>
      <origin xyz="${origin_x} ${origin_y} ${origin_z}" rpy="0 0 0" />
      <mass value="${mass_value}" />
      <inertia
        ixx="${inertia_ixx}"
        ixy="${inertia_ixy}"
        ixz="${inertia_ixz}"
        iyy="${inertia_iyy}"
        iyz="${inertia_iyz}"
        izz="${inertia_izz}" />
    </inertial>

    <visual>
      <origin xyz="0 0 0" rpy="0 0 0" />
      <geometry>
        <mesh filename="${mesh_file}" />
      </geometry>
      <material name="">
        <color rgba="1 1 1 1" />
      </material>
    </visual>

    <collision>
      <origin xyz="0 0 0" rpy="0 0 0" />
      <geometry>
        <mesh filename="${mesh_file}" />
      </geometry>
    </collision>
  </link>

  <gazebo reference="${part_name}_Link">
  </gazebo>

  <joint name="${part_name}_joint" type="revolute">
    <origin xyz="${joint_offset_x} ${joint_offset_y} ${joint_offset_z}" rpy="${joint_offset_rr} ${joint_offset_rp} ${joint_offset_ry}" />
    <parent link="${parent_link}" />
    <child link="${child_link}" />
    <axis xyz="${joint_axis_x} ${joint_axis_y} ${joint_axis_z}" />
    <limit lower="${joint_limit_lower}" upper="${joint_limit_upper}" effort="${joint_limit_effort}" velocity="${joint_limit_velocity}" />
  </joint>

  <gazebo reference="${part_name}_joint">
    <implicitSpringDamper>true</implicitSpringDamper>
  </gazebo>

</robot>
