<?xml version="1.0" encoding="utf-8"?>
<!-- =================================================================================== -->
<!-- |    This document was autogenerated by xacro from yanshee_display.urdf.xacro     | -->
<!-- |    EDITING THIS FILE BY HAND IS NOT RECOMMENDED                                 | -->
<!-- =================================================================================== -->
<robot name="yanshee_gazebo">
  <link name="world">
    <visual>
      <geometry>
        <sphere radius="0.001"/>
      </geometry>
    </visual>
  </link>
  <link name="base_link">
    <inertial>
      <origin rpy="0 0 0" xyz="-0.00671487104263 -0.000225582019654 -0.00799191941195"/>
      <mass value="1.02966120305"/>
      <inertia ixx="0.00180022359518" ixy="1.19183879545e-07" ixz="-5.28660375448e-05" iyy="0.00176811056795" iyz="1.82106435045e-06" izz="0.00168298836268"/>
    </inertial>
    <visual>
      <origin rpy="0 0 0" xyz="0 0 0"/>
      <geometry>
        <mesh filename="package://yanshee/meshes/base_link.STL"/>
      </geometry>
      <material name="">
        <color rgba="1 1 1 1"/>
      </material>
    </visual>
    <collision>
      <origin rpy="0 0 0" xyz="0 0 0"/>
      <geometry>
        <mesh filename="package://yanshee/meshes/base_link.STL"/>
      </geometry>
    </collision>
  </link>
  <gazebo reference="base_link">
  </gazebo>
  <joint name="base_joint" type="fixed">
    <parent link="world"/>
    <child link="base_link"/>
    <origin rpy="0.0 0.0 0.0" xyz="0.0 0.0 0.3"/>
  </joint>
  <link name="head_Link">
    <inertial>
      <origin rpy="0 0 0" xyz="-0.0107920940962 7.80887188769e-05 0.00228460765431"/>
      <mass value="0.0931744907521"/>
      <inertia ixx="2.05515448473e-05" ixy="2.15071905058e-08" ixz="2.68261333174e-06" iyy="4.97323087168e-05" iyz="1.39655887082e-09" izz="5.02600433533e-05"/>
    </inertial>
    <visual>
      <origin rpy="0 0 0" xyz="0 0 0"/>
      <geometry>
        <mesh filename="package://yanshee/meshes/head_Link.STL"/>
      </geometry>
      <material name="">
        <color rgba="1 1 1 1"/>
      </material>
    </visual>
    <collision>
      <origin rpy="0 0 0" xyz="0 0 0"/>
      <geometry>
        <mesh filename="package://yanshee/meshes/head_Link.STL"/>
      </geometry>
    </collision>
  </link>
  <gazebo reference="head_Link">
  </gazebo>
  <joint name="head_joint" type="revolute">
    <origin rpy="0 0 0" xyz="0 -0.00014945 0.06"/>
    <parent link="base_link"/>
    <child link="head_Link"/>
    <axis xyz="-0.00044678 -0.0035302 0.99999"/>
    <limit effort="1.0" lower="-0.78" upper="0.78" velocity="10"/>
    <dynamics damping="5.0" friction="0.0"/>
  </joint>
  <gazebo reference="head_joint">
    <implicitSpringDamper>true</implicitSpringDamper>
  </gazebo>
  <link name="left_arm1_Link">
    <inertial>
      <origin rpy="0 0 0" xyz="5.14775840679e-05 -9.58422844265e-05 -0.011830308656"/>
      <mass value="0.0136649272425"/>
      <inertia ixx="2.36348689886e-06" ixy="-2.43828126653e-12" ixz="2.57000691024e-10" iyy="5.47215996034e-06" iyz="1.05376000101e-09" izz="4.66119879831e-06"/>
    </inertial>
    <visual>
      <origin rpy="0 0 0" xyz="0 0 0"/>
      <geometry>
        <mesh filename="package://yanshee/meshes/left_arm1_Link.STL"/>
      </geometry>
      <material name="">
        <color rgba="1 1 1 1"/>
      </material>
    </visual>
    <collision>
      <origin rpy="0 0 0" xyz="0 0 0"/>
      <geometry>
        <mesh filename="package://yanshee/meshes/left_arm1_Link.STL"/>
      </geometry>
    </collision>
  </link>
  <gazebo reference="left_arm1_Link">
  </gazebo>
  <joint name="left_arm1_joint" type="revolute">
    <origin rpy="-1.5708 0 0" xyz="0.0030003 0.076597 0.013315"/>
    <parent link="base_link"/>
    <child link="left_arm1_Link"/>
    <axis xyz="-5.8802e-05 0 -1"/>
    <limit effort="1" lower="-1.58" upper="1.58" velocity="10"/>
    <dynamics damping="5.0" friction="0.0"/>
  </joint>
  <gazebo reference="left_arm1_joint">
    <implicitSpringDamper>true</implicitSpringDamper>
  </gazebo>
  <link name="left_arm2_Link">
    <inertial>
      <origin rpy="0 0 0" xyz="0.0186297064589 0.000401816051501 -0.000425787006778"/>
      <mass value="0.0156927248265"/>
      <inertia ixx="5.67539816974e-06" ixy="4.73427409516e-08" ixz="4.73427409516e-08" iyy="1.01425535666e-05" iyz="-5.19641927958e-09" izz="8.82186853628e-06"/>
    </inertial>
    <visual>
      <origin rpy="0 0 0" xyz="0 0 0"/>
      <geometry>
        <mesh filename="package://yanshee/meshes/left_arm2_Link.STL"/>
      </geometry>
      <material name="">
        <color rgba="1 1 1 1"/>
      </material>
    </visual>
    <collision>
      <origin rpy="0 0 0" xyz="0 0 0"/>
      <geometry>
        <mesh filename="package://yanshee/meshes/left_arm2_Link.STL"/>
      </geometry>
    </collision>
  </link>
  <gazebo reference="left_arm2_Link">
  </gazebo>
  <joint name="left_arm2_joint" type="revolute">
    <origin rpy="1.5708 0 1.5708" xyz="0 0 0"/>
    <parent link="left_arm1_Link"/>
    <child link="left_arm2_Link"/>
    <axis xyz="0 0 1"/>
    <limit effort="1" lower="-1.58" upper="1.58" velocity="10"/>
    <dynamics damping="5.0" friction="0.0"/>
  </joint>
  <gazebo reference="left_arm2_joint">
    <implicitSpringDamper>true</implicitSpringDamper>
  </gazebo>
  <link name="left_arm3_Link">
    <inertial>
      <origin rpy="0 0 0" xyz="0.0265702745016 9.51803753586e-05 -0.00376690909324"/>
      <mass value="0.0983861935013"/>
      <inertia ixx="1.95628201387e-05" ixy="-4.69255772867e-07" ixz="4.39379554667e-07" iyy="6.21429342122e-05" iyz="1.77682159194e-08" izz="6.01446819208e-05"/>
    </inertial>
    <visual>
      <origin rpy="0 0 0" xyz="0 0 0"/>
      <geometry>
        <mesh filename="package://yanshee/meshes/left_arm3_Link.STL"/>
      </geometry>
      <material name="">
        <color rgba="1 1 1 1"/>
      </material>
    </visual>
    <collision>
      <origin rpy="0 0 0" xyz="0 0 0"/>
      <geometry>
        <mesh filename="package://yanshee/meshes/left_arm3_Link.STL"/>
      </geometry>
    </collision>
  </link>
  <gazebo reference="left_arm3_Link">
  </gazebo>
  <joint name="left_arm3_joint" type="revolute">
    <origin rpy="0 0 0" xyz="0.059245 0 0.00152"/>
    <parent link="left_arm2_Link"/>
    <child link="left_arm3_Link"/>
    <axis xyz="0.026177 0 0.99966"/>
    <limit effort="1" lower="-1.58" upper="1.58" velocity="10"/>
    <dynamics damping="5.0" friction="0.0"/>
  </joint>
  <gazebo reference="left_arm3_joint">
    <implicitSpringDamper>true</implicitSpringDamper>
  </gazebo>
  <link name="right_arm1_Link">
    <inertial>
      <origin rpy="0 0 0" xyz="-5.14775871424e-05 -9.58421639294e-05 -0.011830308656"/>
      <mass value="0.0136649272424"/>
      <inertia ixx="2.3634868989e-06" ixy="2.43827204008e-12" ixz="-2.57000159418e-10" iyy="5.47215996034e-06" iyz="1.05373950043e-09" izz="4.66119879834e-06"/>
    </inertial>
    <visual>
      <origin rpy="0 0 0" xyz="0 0 0"/>
      <geometry>
        <mesh filename="package://yanshee/meshes/right_arm1_Link.STL"/>
      </geometry>
      <material name="">
        <color rgba="1 1 1 1"/>
      </material>
    </visual>
    <collision>
      <origin rpy="0 0 0" xyz="0 0 0"/>
      <geometry>
        <mesh filename="package://yanshee/meshes/right_arm1_Link.STL"/>
      </geometry>
    </collision>
  </link>
  <joint name="right_arm1_joint" type="revolute">
    <origin rpy="1.5708 0 0" xyz="0.0030003 -0.077273 0.013316"/>
    <parent link="base_link"/>
    <child link="right_arm1_Link"/>
    <axis xyz="0 0 1"/>
    <limit effort="1" lower="-1.58" upper="1.58" velocity="10"/>
    <dynamics damping="5.0" friction="0.0"/>
  </joint>
  <gazebo reference="right_arm1_joint">
    <implicitSpringDamper>true</implicitSpringDamper>
  </gazebo>
  <link name="right_arm2_Link">
    <inertial>
      <origin rpy="0 0 0" xyz="0.0186297095059 0.000401688645375 0.00042591771828"/>
      <mass value="0.0156926957"/>
      <inertia ixx="5.67540894238e-06" ixy="4.73622619858e-08" ixz="1.27913953579e-07" iyy="1.01425587967e-05" iyz="5.1455618647e-09" izz="8.8218799658e-06"/>
    </inertial>
    <visual>
      <origin rpy="0 0 0" xyz="0 0 0"/>
      <geometry>
        <mesh filename="package://yanshee/meshes/right_arm2_Link.STL"/>
      </geometry>
      <material name="">
        <color rgba="1 1 1 1"/>
      </material>
    </visual>
    <collision>
      <origin rpy="0 0 0" xyz="0 0 0"/>
      <geometry>
        <mesh filename="package://yanshee/meshes/right_arm2_Link.STL"/>
      </geometry>
    </collision>
  </link>
  <gazebo reference="right_arm2">
  </gazebo>
  <joint name="right_arm2_joint" type="revolute">
    <origin rpy="1.5708 0 -1.5708" xyz="-9.961e-05 0 0"/>
    <parent link="right_arm1_Link"/>
    <child link="right_arm2_Link"/>
    <axis xyz="0 0 1"/>
    <limit effort="1" lower="-1.58" upper="1.58" velocity="10"/>
    <dynamics damping="5.0" friction="0.0"/>
  </joint>
  <gazebo reference="right_arm2_joint">
    <implicitSpringDamper>true</implicitSpringDamper>
  </gazebo>
  <link name="right_arm3_Link">
    <inertial>
      <origin rpy="0 0 0" xyz="0.0266597021833 9.51783873687e-05 0.00307009292756"/>
      <mass value="0.098385286974"/>
      <inertia ixx="1.95671253597e-05" ixy="-4.69557130989e-07" ixz="6.23165184228e-07" iyy="6.2142544546e-05" iyz="-5.47676812377e-09" izz="6.01395038406e-05"/>
    </inertial>
    <visual>
      <origin rpy="0 0 0" xyz="0 0 0"/>
      <geometry>
        <mesh filename="package://yanshee/meshes/right_arm3_Link.STL"/>
      </geometry>
      <material name="">
        <color rgba="1 1 1 1"/>
      </material>
    </visual>
    <collision>
      <origin rpy="0 0 0" xyz="0 0 0"/>
      <geometry>
        <mesh filename="package://yanshee/meshes/right_arm3_Link.STL"/>
      </geometry>
    </collision>
  </link>
  <gazebo reference="right_arm3">
  </gazebo>
  <joint name="right_arm3_joint" type="revolute">
    <origin rpy="0 0 0" xyz="0.059245 0 -0.00152"/>
    <parent link="right_arm2_Link"/>
    <child link="right_arm3_Link"/>
    <axis xyz="0 0 -1"/>
    <limit effort="1" lower="-1.58" upper="1.58" velocity="10"/>
    <dynamics damping="5.0" friction="0.0"/>
  </joint>
  <gazebo reference="right_arm3_joint">
    <implicitSpringDamper>true</implicitSpringDamper>
  </gazebo>
  <link name="left_leg1_Link">
    <inertial>
      <origin rpy="0 0 0" xyz="0.0218793806246 0.000461528315038 0.000437328945235"/>
      <mass value="0.0156559636609"/>
      <inertia ixx="4.47155922342e-06" ixy="-1.77585864344e-07" ixz="1.75175041215e-07" iyy="4.61839887542e-06" iyz="3.15996181845e-09" izz="4.61590434525e-06"/>
    </inertial>
    <visual>
      <origin rpy="0 0 0" xyz="0 0 0"/>
      <geometry>
        <mesh filename="package://yanshee/meshes/left_leg1_Link.STL"/>
      </geometry>
      <material name="">
        <color rgba="1 1 1 1"/>
      </material>
    </visual>
    <collision>
      <origin rpy="0 0 0" xyz="0 0 0"/>
      <geometry>
        <mesh filename="package://yanshee/meshes/left_leg1_Link.STL"/>
      </geometry>
    </collision>
  </link>
  <gazebo reference="left_leg1_Link">
  </gazebo>
  <joint name="left_leg1_joint" type="revolute">
    <origin rpy="-1.5708 1.5708 1.5708" xyz="-0.0091403 0.028469 -0.066034"/>
    <parent link="base_link"/>
    <child link="left_leg1_Link"/>
    <axis xyz="0 0 -1"/>
    <limit effort="1" lower="-1.58" upper="1.58" velocity="10"/>
  </joint>
  <gazebo reference="left_leg1_joint">
    <implicitSpringDamper>true</implicitSpringDamper>
  </gazebo>
  <link name="left_leg2_Link">
    <inertial>
      <origin rpy="0 0 0" xyz="0.0255864571187 -0.0108509305855 0.00101864247276"/>
      <mass value="0.10771515023"/>
      <inertia ixx="3.38164419926e-05" ixy="1.23153518588e-05" ixz="4.61942112712e-07" iyy="5.78640129364e-05" iyz="2.74795544045e-07" izz="6.6483992751e-05"/>
    </inertial>
    <visual>
      <origin rpy="0 0 0" xyz="0 0 0"/>
      <geometry>
        <mesh filename="package://yanshee/meshes/left_leg2_Link.STL"/>
      </geometry>
      <material name="">
        <color rgba="1 1 1 1"/>
      </material>
    </visual>
    <collision>
      <origin rpy="0 0 0" xyz="0 0 0"/>
      <geometry>
        <mesh filename="package://yanshee/meshes/left_leg2_Link.STL"/>
      </geometry>
    </collision>
  </link>
  <gazebo reference="left_leg2">
  </gazebo>
  <joint name="left_leg2_joint" type="revolute">
    <origin rpy="1.5708 0 0" xyz="0.0438 0 0"/>
    <parent link="left_leg1_Link"/>
    <child link="left_leg2_Link"/>
    <axis xyz="0 0 -1"/>
    <limit effort="1" lower="-1.58" upper="1.58" velocity="10"/>
  </joint>
  <gazebo reference="left_leg2_joint">
    <implicitSpringDamper>true</implicitSpringDamper>
  </gazebo>
  <link name="left_leg3_Link">
    <inertial>
      <origin rpy="0 0 0" xyz="0.0407946525784 2.00999895416e-05 0.000215900493276"/>
      <mass value="0.076970591262"/>
      <inertia ixx="2.01778905648e-05" ixy="3.2477041201e-09" ixz="-5.11455121015e-08" iyy="3.91841731233e-05" iyz="1.50114743012e-09" izz="3.21700138168e-05"/>
    </inertial>
    <visual>
      <origin rpy="0 0 0" xyz="0 0 0"/>
      <geometry>
        <mesh filename="package://yanshee/meshes/left_leg3_Link.STL"/>
      </geometry>
      <material name="">
        <color rgba="1 1 1 1"/>
      </material>
    </visual>
    <collision>
      <origin rpy="0 0 0" xyz="0 0 0"/>
      <geometry>
        <mesh filename="package://yanshee/meshes/left_leg3_Link.STL"/>
      </geometry>
    </collision>
  </link>
  <gazebo reference="left_leg3_Link">
  </gazebo>
  <joint name="left_leg3_joint" type="revolute">
    <origin rpy="0 0 0" xyz="0.049876 0 1.4223e-05"/>
    <parent link="left_leg2_Link"/>
    <child link="left_leg3_Link"/>
    <axis xyz="0 0.0007632 -1"/>
    <limit effort="1" lower="-1.58" upper="1.58" velocity="10"/>
  </joint>
  <gazebo reference="left_leg3_joint">
    <implicitSpringDamper>true</implicitSpringDamper>
  </gazebo>
  <link name="left_leg4_Link">
    <inertial>
      <origin rpy="0 0 0" xyz="0.0339764234952 0.00157592235511 0.000681683144301"/>
      <mass value="0.037747033804"/>
      <inertia ixx="9.39593056661e-06" ixy="-1.98740237705e-07" ixz="-6.93339605999e-08" iyy="6.29756290524e-06" iyz="2.15786874188e-07" izz="9.74973254351e-06"/>
    </inertial>
    <visual>
      <origin rpy="0 0 0" xyz="0 0 0"/>
      <geometry>
        <mesh filename="package://yanshee/meshes/left_leg4_Link.STL"/>
      </geometry>
      <material name="">
        <color rgba="1 1 1 1"/>
      </material>
    </visual>
    <collision>
      <origin rpy="0 0 0" xyz="0 0 0"/>
      <geometry>
        <mesh filename="package://yanshee/meshes/left_leg4_Link.STL"/>
      </geometry>
    </collision>
  </link>
  <gazebo reference="left_leg4_Link">
  </gazebo>
  <joint name="left_leg4_joint" type="revolute">
    <origin rpy="1.5708 0 0" xyz="0.059245 1.5251e-05 0"/>
    <parent link="left_leg3_Link"/>
    <child link="left_leg4_Link"/>
    <axis xyz="0 -1 0"/>
    <limit effort="1" lower="-1.58" upper="1.58" velocity="10"/>
  </joint>
  <gazebo reference="left_leg4_joint">
    <implicitSpringDamper>true</implicitSpringDamper>
  </gazebo>
  <link name="left_leg5_Link">
    <inertial>
      <origin rpy="0 0 0" xyz="0.0196730138541 -0.0233092637107 -0.00142039915584"/>
      <mass value="0.18069344878"/>
      <inertia ixx="0.000286904706763" ixy="4.85308988509e-07" ixz="3.086122017e-08" iyy="0.00020996168855" iyz="2.86937724082e-10" izz="0.000102539066832"/>
    </inertial>
    <visual>
      <origin rpy="0 0 0" xyz="0 0 0"/>
      <geometry>
        <mesh filename="package://yanshee/meshes/left_leg5_Link.STL"/>
      </geometry>
      <material name="">
        <color rgba="1 1 1 1"/>
      </material>
    </visual>
    <collision>
      <origin rpy="0 0 0" xyz="0 0 0"/>
      <geometry>
        <mesh filename="package://yanshee/meshes/left_leg5_Link.STL"/>
      </geometry>
    </collision>
  </link>
  <gazebo reference="left_leg5_Link">
  </gazebo>
  <joint name="left_leg5_joint" type="revolute">
    <origin rpy="3.1416 0 0" xyz="0.03699 -0.0088627 0"/>
    <parent link="left_leg4_Link"/>
    <child link="left_leg5_Link"/>
    <axis xyz="0 0 -1"/>
    <limit effort="1" lower="-1.58" upper="1.58" velocity="10"/>
  </joint>
  <gazebo reference="left_leg5_joint">
    <implicitSpringDamper>true</implicitSpringDamper>
  </gazebo>
  <link name="right_leg1_Link">
    <inertial>
      <origin rpy="0 0 0" xyz="0.0218793806256 0.000461528344157 -0.000437328923432"/>
      <mass value="0.0156559636636"/>
      <inertia ixx="4.47155922611e-06" ixy="-1.77585863984e-07" ixz="-1.75175041215e-07" iyy="4.61839887542e-06" iyz="-3.15996181845e-09" izz="4.61590434525e-06"/>
    </inertial>
    <visual>
      <origin rpy="0 0 0" xyz="0 0 0"/>
      <geometry>
        <mesh filename="package://yanshee/meshes/right_leg1_Link.STL"/>
      </geometry>
      <material name="">
        <color rgba="1 1 1 1"/>
      </material>
    </visual>
    <collision>
      <origin rpy="0 0 0" xyz="0 0 0"/>
      <geometry>
        <mesh filename="package://yanshee/meshes/right_leg1_Link.STL"/>
      </geometry>
    </collision>
  </link>
  <gazebo reference="right_leg1">
  </gazebo>
  <joint name="right_leg1_joint" type="revolute">
    <origin rpy="-1.5708 1.5708 -1.5708" xyz="-0.0091403 -0.028469 -0.066034"/>
    <parent link="base_link"/>
    <child link="right_leg1_Link"/>
    <axis xyz="0 0 1"/>
    <limit effort="1" lower="-1.58" upper="1.58" velocity="10"/>
  </joint>
  <gazebo reference="right_leg1_joint">
    <implicitSpringDamper>true</implicitSpringDamper>
  </gazebo>
  <link name="right_leg2_Link">
    <inertial>
      <origin rpy="0 0 0" xyz="0.0248207221658 0.0125036435026 0.00101864810052"/>
      <mass value="0.10771523716"/>
      <inertia ixx="3.55296285134e-05" ixy="-1.37815242879e-05" ixz="4.78946454291e-07" iyy="5.61509322468e-05" iyz="-2.43945783167e-07" izz="6.6484003646e-05"/>
    </inertial>
    <visual>
      <origin rpy="0 0 0" xyz="0 0 0"/>
      <geometry>
        <mesh filename="package://yanshee/meshes/right_leg2_Link.STL"/>
      </geometry>
      <material name="">
        <color rgba="1 1 1 1"/>
      </material>
    </visual>
    <collision>
      <origin rpy="0 0 0" xyz="0 0 0"/>
      <geometry>
        <mesh filename="package://yanshee/meshes/right_leg2_Link.STL"/>
      </geometry>
    </collision>
  </link>
  <gazebo reference="right_leg2">
  </gazebo>
  <joint name="right_leg2_joint" type="revolute">
    <origin rpy="1.5708 0 0" xyz="0.0438 0 0"/>
    <parent link="right_leg1_Link"/>
    <child link="right_leg2_Link"/>
    <axis xyz="0 0 -1"/>
    <limit effort="1" lower="-1.58" upper="1.58" velocity="10"/>
  </joint>
  <gazebo reference="right_leg2_joint">
    <implicitSpringDamper>true</implicitSpringDamper>
  </gazebo>
  <link name="right_leg3_Link">
    <inertial>
      <origin rpy="0 0 0" xyz="0.0407948464152 -2.01710272296e-05 0.000215807538541"/>
      <mass value="0.0769703186436"/>
      <inertia ixx="2.01778686734e-05" ixy="-3.22661324796e-09" ixz="-5.14487015473e-08" iyy="3.9183391917e-05" iyz="3.8374281595e-09" izz="3.21693080984e-05"/>
    </inertial>
    <visual>
      <origin rpy="0 0 0" xyz="0 0 0"/>
      <geometry>
        <mesh filename="package://yanshee/meshes/right_leg3_Link.STL"/>
      </geometry>
      <material name="">
        <color rgba="1 1 1 1"/>
      </material>
    </visual>
    <collision>
      <origin rpy="0 0 0" xyz="0 0 0"/>
      <geometry>
        <mesh filename="package://yanshee/meshes/right_leg3_Link.STL"/>
      </geometry>
    </collision>
  </link>
  <gazebo reference="right_leg3">
  </gazebo>
  <joint name="right_leg3_joint" type="revolute">
    <origin rpy="0 0 0" xyz="0.049769 0.0032671 1.4223e-05"/>
    <parent link="right_leg2_Link"/>
    <child link="right_leg3_Link"/>
    <axis xyz="0 0.0007632 -1"/>
    <limit effort="1" lower="-1.58" upper="1.58" velocity="10"/>
  </joint>
  <gazebo reference="right_leg3_joint">
    <implicitSpringDamper>true</implicitSpringDamper>
  </gazebo>
  <link name="right_leg4_Link">
    <inertial>
      <origin rpy="0 0 0" xyz="0.0339764646324 0.00068137145058 0.00157592285559"/>
      <mass value="0.0377471105565"/>
      <inertia ixx="9.39595739029e-06" ixy="-6.93417906435e-08" ixz="-1.98734856223e-07" iyy="9.74975907788e-06" iyz="2.1581610484e-07" izz="6.29758000244e-06"/>
    </inertial>
    <visual>
      <origin rpy="0 0 0" xyz="0 0 0"/>
      <geometry>
        <mesh filename="package://yanshee/meshes/right_leg4_Link.STL"/>
      </geometry>
      <material name="">
        <color rgba="1 1 1 1"/>
      </material>
    </visual>
    <collision>
      <origin rpy="0 0 0" xyz="0 0 0"/>
      <geometry>
        <mesh filename="package://yanshee/meshes/right_leg4_Link.STL"/>
      </geometry>
    </collision>
  </link>
  <gazebo reference="right_leg4">
  </gazebo>
  <joint name="right_leg4_joint" type="revolute">
    <origin rpy="0 0 0" xyz="0.059245 -1.5243e-05 -1.0003e-05"/>
    <parent link="right_leg3_Link"/>
    <child link="right_leg4_Link"/>
    <axis xyz="0 0 -1"/>
    <limit effort="1" lower="-1.58" upper="1.58" velocity="10"/>
  </joint>
  <gazebo reference="right_leg4_joint">
    <implicitSpringDamper>true</implicitSpringDamper>
  </gazebo>
  <link name="right_leg5_Link">
    <inertial>
      <origin rpy="0 0 0" xyz="0.0196728894918 -0.023309336199 0.00142044913562"/>
      <mass value="0.180690409171"/>
      <inertia ixx="0.000286894196606" ixy="4.85195544577e-07" ixz="-3.07943743531e-08" iyy="0.000209955979974" iyz="-1.37393316499e-09" izz="0.000102534173179"/>
    </inertial>
    <visual>
      <origin rpy="0 0 0" xyz="0 0 0"/>
      <geometry>
        <mesh filename="package://yanshee/meshes/right_leg5_Link.STL"/>
      </geometry>
      <material name="">
        <color rgba="1 1 1 1"/>
      </material>
    </visual>
    <collision>
      <origin rpy="0 0 0" xyz="0 0 0"/>
      <geometry>
        <mesh filename="package://yanshee/meshes/right_leg5_Link.STL"/>
      </geometry>
    </collision>
  </link>
  <gazebo reference="right_leg5">
  </gazebo>
  <joint name="right_leg5_joint" type="revolute">
    <origin rpy="-1.5708 0 0" xyz="0.03699 0 -0.0088627"/>
    <parent link="right_leg4_Link"/>
    <child link="right_leg5_Link"/>
    <axis xyz="0 0 1"/>
    <limit effort="1" lower="-1.58" upper="1.58" velocity="10"/>
  </joint>
  <gazebo reference="right_leg5_joint">
    <implicitSpringDamper>true</implicitSpringDamper>
  </gazebo>
  <transmission name="head_tran">
    <type>transmission_interface/SimpleTransmission</type>
    <joint name="head_joint">
      <hardwareInterface>hardware_interface/PositionJointInterface</hardwareInterface>
    </joint>
    <actuator name="head_motor">
      <hardwareInterface>hardware_interface/PositionJointInterface</hardwareInterface>
      <mechanicalReduction>1</mechanicalReduction>
    </actuator>
  </transmission>
  <transmission name="left_arm1_tran">
    <type>transmission_interface/SimpleTransmission</type>
    <joint name="left_arm1_joint">
      <hardwareInterface>hardware_interface/PositionJointInterface</hardwareInterface>
    </joint>
    <actuator name="left_arm1_motor">
      <hardwareInterface>hardware_interface/PositionJointInterface</hardwareInterface>
      <mechanicalReduction>1</mechanicalReduction>
    </actuator>
  </transmission>
  <transmission name="left_arm2_tran">
    <type>transmission_interface/SimpleTransmission</type>
    <joint name="left_arm2_joint">
      <hardwareInterface>hardware_interface/PositionJointInterface</hardwareInterface>
    </joint>
    <actuator name="left_arm2_motor">
      <hardwareInterface>hardware_interface/PositionJointInterface</hardwareInterface>
      <mechanicalReduction>1</mechanicalReduction>
    </actuator>
  </transmission>
  <transmission name="left_arm3_tran">
    <type>transmission_interface/SimpleTransmission</type>
    <joint name="left_arm3_joint">
      <hardwareInterface>hardware_interface/PositionJointInterface</hardwareInterface>
    </joint>
    <actuator name="left_arm3_motor">
      <hardwareInterface>hardware_interface/PositionJointInterface</hardwareInterface>
      <mechanicalReduction>1</mechanicalReduction>
    </actuator>
  </transmission>
  <transmission name="right_arm1_tran">
    <type>transmission_interface/SimpleTransmission</type>
    <joint name="right_arm1_joint">
      <hardwareInterface>hardware_interface/PositionJointInterface</hardwareInterface>
    </joint>
    <actuator name="right_arm1_motor">
      <hardwareInterface>hardware_interface/PositionJointInterface</hardwareInterface>
      <mechanicalReduction>1</mechanicalReduction>
    </actuator>
  </transmission>
  <transmission name="right_arm2_tran">
    <type>transmission_interface/SimpleTransmission</type>
    <joint name="right_arm2_joint">
      <hardwareInterface>hardware_interface/PositionJointInterface</hardwareInterface>
    </joint>
    <actuator name="right_arm2_motor">
      <hardwareInterface>hardware_interface/PositionJointInterface</hardwareInterface>
      <mechanicalReduction>1</mechanicalReduction>
    </actuator>
  </transmission>
  <transmission name="right_arm3_tran">
    <type>transmission_interface/SimpleTransmission</type>
    <joint name="right_arm3_joint">
      <hardwareInterface>hardware_interface/PositionJointInterface</hardwareInterface>
    </joint>
    <actuator name="right_arm3_motor">
      <hardwareInterface>hardware_interface/PositionJointInterface</hardwareInterface>
      <mechanicalReduction>1</mechanicalReduction>
    </actuator>
  </transmission>
  <transmission name="left_leg1_tran">
    <type>transmission_interface/SimpleTransmission</type>
    <joint name="left_leg1_joint">
      <hardwareInterface>hardware_interface/PositionJointInterface</hardwareInterface>
    </joint>
    <actuator name="left_leg1_motor">
      <hardwareInterface>hardware_interface/PositionJointInterface</hardwareInterface>
      <mechanicalReduction>1</mechanicalReduction>
    </actuator>
  </transmission>
  <transmission name="left_leg2_tran">
    <type>transmission_interface/SimpleTransmission</type>
    <joint name="left_leg2_joint">
      <hardwareInterface>hardware_interface/PositionJointInterface</hardwareInterface>
    </joint>
    <actuator name="left_leg2_motor">
      <hardwareInterface>hardware_interface/PositionJointInterface</hardwareInterface>
      <mechanicalReduction>1</mechanicalReduction>
    </actuator>
  </transmission>
  <transmission name="left_leg3_tran">
    <type>transmission_interface/SimpleTransmission</type>
    <joint name="left_leg3_joint">
      <hardwareInterface>hardware_interface/PositionJointInterface</hardwareInterface>
    </joint>
    <actuator name="left_leg3_motor">
      <hardwareInterface>hardware_interface/PositionJointInterface</hardwareInterface>
      <mechanicalReduction>1</mechanicalReduction>
    </actuator>
  </transmission>
  <transmission name="left_leg4_tran">
    <type>transmission_interface/SimpleTransmission</type>
    <joint name="left_leg4_joint">
      <hardwareInterface>hardware_interface/PositionJointInterface</hardwareInterface>
    </joint>
    <actuator name="left_leg4_motor">
      <hardwareInterface>hardware_interface/PositionJointInterface</hardwareInterface>
      <mechanicalReduction>1</mechanicalReduction>
    </actuator>
  </transmission>
  <transmission name="left_leg5_tran">
    <type>transmission_interface/SimpleTransmission</type>
    <joint name="left_leg5_joint">
      <hardwareInterface>hardware_interface/PositionJointInterface</hardwareInterface>
    </joint>
    <actuator name="left_leg5_motor">
      <hardwareInterface>hardware_interface/PositionJointInterface</hardwareInterface>
      <mechanicalReduction>1</mechanicalReduction>
    </actuator>
  </transmission>
  <transmission name="right_leg1_tran">
    <type>transmission_interface/SimpleTransmission</type>
    <joint name="right_leg1_joint">
      <hardwareInterface>hardware_interface/PositionJointInterface</hardwareInterface>
    </joint>
    <actuator name="right_leg1_motor">
      <hardwareInterface>hardware_interface/PositionJointInterface</hardwareInterface>
      <mechanicalReduction>1</mechanicalReduction>
    </actuator>
  </transmission>
  <transmission name="right_leg2_tran">
    <type>transmission_interface/SimpleTransmission</type>
    <joint name="right_leg2_joint">
      <hardwareInterface>hardware_interface/PositionJointInterface</hardwareInterface>
    </joint>
    <actuator name="right_leg2_motor">
      <hardwareInterface>hardware_interface/PositionJointInterface</hardwareInterface>
      <mechanicalReduction>1</mechanicalReduction>
    </actuator>
  </transmission>
  <transmission name="right_leg3_tran">
    <type>transmission_interface/SimpleTransmission</type>
    <joint name="right_leg3_joint">
      <hardwareInterface>hardware_interface/PositionJointInterface</hardwareInterface>
    </joint>
    <actuator name="right_leg3_motor">
      <hardwareInterface>hardware_interface/PositionJointInterface</hardwareInterface>
      <mechanicalReduction>1</mechanicalReduction>
    </actuator>
  </transmission>
  <transmission name="right_leg4_tran">
    <type>transmission_interface/SimpleTransmission</type>
    <joint name="right_leg4_joint">
      <hardwareInterface>hardware_interface/PositionJointInterface</hardwareInterface>
    </joint>
    <actuator name="right_leg4_motor">
      <hardwareInterface>hardware_interface/PositionJointInterface</hardwareInterface>
      <mechanicalReduction>1</mechanicalReduction>
    </actuator>
  </transmission>
  <transmission name="right_leg5_tran">
    <type>transmission_interface/SimpleTransmission</type>
    <joint name="right_leg5_joint">
      <hardwareInterface>hardware_interface/PositionJointInterface</hardwareInterface>
    </joint>
    <actuator name="right_leg5_motor">
      <hardwareInterface>hardware_interface/PositionJointInterface</hardwareInterface>
      <mechanicalReduction>1</mechanicalReduction>
    </actuator>
  </transmission>
  <gazebo>
    <plugin filename="libgazebo_ros_control.so" name="gazebo_ros_control">
      <robotNamespace>/yanshee</robotNamespace>
      <robotSimType>gazebo_ros_control/DefaultRobotHWSim</robotSimType>
    </plugin>
  </gazebo>
</robot>

