<robot name="right_leg3" xmlns:xacro="http://wiki.ros.org/xacro">
  <xacro:property name="part_name" value="right_leg3" />
  <xacro:property name="origin_x" value="0.0407948464152487" />
  <xacro:property name="origin_y" value="-2.01710272295947E-05" />
  <xacro:property name="origin_z" value="0.000215807538541168" />
  <xacro:property name="mass_value" value="0.0769703186436065" />


  <xacro:property name="inertia_ixx" value="2.01778686734398E-05" />
  <xacro:property name="inertia_ixy" value="-3.2266132479563E-09" />
  <xacro:property name="inertia_ixz" value="-5.14487015473355E-08" />
  <xacro:property name="inertia_iyy" value="3.91833919170359E-05" />
  <xacro:property name="inertia_iyz" value="3.83742815950406E-09" />
  <xacro:property name="inertia_izz" value="3.21693080984243E-05" /> 

  <xacro:property name="mesh_file" value="package://yanshee/meshes/right_leg3_Link.STL" />

  <xacro:property name="joint_offset_x" value="0.049769" />
  <xacro:property name="joint_offset_y" value="0.0032671" />
  <xacro:property name="joint_offset_z" value="1.4223E-05" />
  <xacro:property name="joint_offset_rr" value="0" />
  <xacro:property name="joint_offset_rp" value="0" />
  <xacro:property name="joint_offset_ry" value="0" />

  <xacro:property name="parent_link" value="right_leg2_Link" />
  <xacro:property name="child_link" value="right_leg3_Link" />

  <xacro:property name="joint_axis_x" value="0" />
  <xacro:property name="joint_axis_y" value="0.0007632" />
  <xacro:property name="joint_axis_z" value="-1" />

  <xacro:property name="joint_limit_lower" value="-1.58" />
  <xacro:property name="joint_limit_upper" value="1.58" />
  <xacro:property name="joint_limit_effort" value="1" />
  <xacro:property name="joint_limit_velocity" value="10" />




  <link name="${part_name}_Link">
    <inertial>
      <origin xyz="${origin_x} ${origin_y} ${origin_z}" rpy="0 0 0" />
      <mass value="${mass_value}" />
      <inertia
        ixx="${inertia_ixx}"
        ixy="${inertia_ixy}"
        ixz="${inertia_ixz}"
        iyy="${inertia_iyy}"
        iyz="${inertia_iyz}"
        izz="${inertia_izz}" />
    </inertial>

    <visual>
      <origin xyz="0 0 0" rpy="0 0 0" />
      <geometry>
        <mesh filename="${mesh_file}" />
      </geometry>
      <material name="">
        <color rgba="1 1 1 1" />
      </material>
    </visual>

    <collision>
      <origin xyz="0 0 0" rpy="0 0 0" />
      <geometry>
        <mesh filename="${mesh_file}" />
      </geometry>
    </collision>
  </link>

  <gazebo reference="${part_name}">
  </gazebo>

  <joint name="${part_name}_joint" type="revolute">
    <origin xyz="${joint_offset_x} ${joint_offset_y} ${joint_offset_z}" rpy="${joint_offset_rr} ${joint_offset_rp} ${joint_offset_ry}" />
    <parent link="${parent_link}" />
    <child link="${child_link}" />
    <axis xyz="${joint_axis_x} ${joint_axis_y} ${joint_axis_z}" />
    <limit lower="${joint_limit_lower}" upper="${joint_limit_upper}" effort="${joint_limit_effort}" velocity="${joint_limit_velocity}" />
  </joint>


  <gazebo reference="${part_name}_joint">
    <implicitSpringDamper>true</implicitSpringDamper>
  </gazebo>

</robot>
